Workbook

Sheet Cleaned_Data
A1: user_id | B1: signup_date | C1: experiment_group | D1: region | E1: device_type | F1: traffic_source | G1: plan_type | H1: visited_landing_page | I1: started_trial | J1: completed_onboarding | K1: converted_to_paid | L1: revenue_30d | M1: support_tickets_30d | N1: refund_requested | O1: days_to_convert | P1: engagement_score
A2: USR-100001 | B2: 45732 | C2: Control | D2: North | E2: Desktop | F2: Email | G2: Basic | H2: 0 | I2: 0 | J2: 0 | K2: 0 | L2: 0 | M2: 0 | N2: 0 | P2: 45.7
A3: USR-100002 | B3: 45724 | C3: Control | D3: West | E3: Mobile | F3: Organic | G3: Free | H3: 1 | I3: 0 | J3: 0 | K3: 0 | L3: 0 | M3: 0 | N3: 0 | P3: 48.6
A4: USR-100003 | B4: 45771 | C4: Control | D4: East | E4: Mobile | F4: Paid Search | G4: Premium | H4: 1 | I4: 0 | J4: 0 | K4: 0 | L4: 0 | M4: 1 | N4: 0 | P4: 35.4
A5: USR-100004 | B5: 45781 | C5: Control | D5: South | E5: Mobile | F5: Email | G5: Basic | H5: 1 | I5: 0 | J5: 0 | K5: 0 | L5: 0 | M5: 0 | N5: 0 | P5: 64.6
A6: USR-100005 | B6: 45700 | C6: Control | D6: North | E6: Tablet | F6: Organic | G6: Free | H6: 0 | I6: 0 | J6: 0 | K6: 0 | L6: 0 | M6: 0 | N6: 0 | P6: 66.6
A7: USR-100006 | B7: 45685 | C7: Control | D7: East | E7: Mobile | F7: Organic | G7: Premium | H7: 1 | I7: 0 | J7: 0 | K7: 0 | L7: 0 | M7: 0 | N7: 0 | P7: 40.8
A8: USR-100007 | B8: 45755 | C8: Control | D8: East | E8: Mobile | F8: Paid Search | G8: Basic | H8: 1 | I8: 1 | J8: 0 | K8: 0 | L8: 0 | M8: 0 | N8: 0 | P8: 57.1
A9: USR-100008 | B9: 45794 | C9: Control | D9: South | E9: Mobile | F9: Paid Search | G9: Free | H9: 0 | I9: 0 | J9: 0 | K9: 0 | L9: 0 | M9: 0 | N9: 0 | P9: 36.4
A10: USR-100009 | B10: 45711 | C10: Control | D10: South | E10: Tablet | F10: Referral | G10: Basic | H10: 0 | I10: 0 | J10: 0 | K10: 0 | L10: 0 | M10: 0 | N10: 0 | P10: 55.4
A11: USR-100010 | B11: 45806 | C11: Control | D11: West | E11: Desktop | F11: Social | G11: Free | H11: 1 | I11: 0 | J11: 0 | K11: 0 | L11: 0 | M11: 0 | N11: 0 | P11: 57.3
A12: USR-100011 | B12: 45777 | C12: Control | D12: East | E12: Mobile | F12: Paid Search | G12: Basic | H12: 1 | I12: 1 | J12: 1 | K12: 0 | L12: 0 | M12: 0 | N12: 0 | P12: 63.6
A13: USR-100012 | B13: 45732 | C13: Control | D13: East | E13: Mobile | F13: Social | G13: Premium | H13: 1 | I13: 1 | J13: 1 | K13: 0 | L13: 0 | M13: 1 | N13: 0 | P13: 80.4
... A60: USR-100059 | B60: 45761 | C60: Control | D60: North | E60: Mobile | F60: Social | G60: Free | H60: 0 | I60: 0 | J60: 0 | K60: 0 | L60: 0 | M60: 2 | N60: 0 | P60: 48.9
A61: USR-100060 | B61: 45658 | C61: Control | D61: West | E61: Mobile | F61: Social | G61: Free | H61: 1 | I61: 1 | J61: 1 | K61: 1 | L61: 240.42 | M61: 0 | N61: 0 | O61: 16 | P61: 56.5
A62: USR-100061 | B62: 45749 | C62: Control | D62: South | E62: Mobile | F62: Referral | G62: Free | H62: 1 | I62: 0 | J62: 0 | K62: 0 | L62: 0 | M62: 0 | N62: 0 | P62: 53.7
A63: USR-100062 | B63: 45745 | C63: Control | D63: North | E63: Mobile | F63: Social | G63: Premium | H63: 0 | I63: 0 | J63: 0 | K63: 0 | L63: 0 | M63: 0 | N63: 0 | P63: 62.2
A64: USR-100063 | B64: 45792 | C64: Control | D64: South | E64: Desktop | F64: Organic | G64: Free | H64: 1 | I64: 0 | J64: 0 | K64: 0 | L64: 0 | M64: 0 | N64: 0 | P64: 50.2
A65: USR-100064 | B65: 45758 | C65: Control | D65: North | E65: Mobile | F65: Organic | G65: Basic | H65: 1 | I65: 0 | J65: 0 | K65: 0 | L65: 0 | M65: 0 | N65: 0 | P65: 74.3
A66: USR-100065 | B66: 45723 | C66: Control | D66: South | E66: Desktop | F66: Paid Search | G66: Free | H66: 1 | I66: 0 | J66: 0 | K66: 0 | L66: 0 | M66: 0 | N66: 0 | P66: 58
A67: USR-100066 | B67: 45807 | C67: Control | D67: South | E67: Mobile | F67: Organic | G67: Free | H67: 0 | I67: 0 | J67: 0 | K67: 0 | L67: 0 | M67: 0 | N67: 0 | P67: 46.7
A68: USR-100067 | B68: 45664 | C68: Control | D68: South | E68: Desktop | F68: Organic | G68: Premium | H68: 1 | I68: 0 | J68: 0 | K68: 0 | L68: 0 | M68: 1 | N68: 0 | P68: 49.6
A69: USR-100068 | B69: 45785 | C69: Control | D69: West | E69: Mobile | F69: Social | G69: Free | H69: 0 | I69: 0 | J69: 0 | K69: 0 | L69: 0 | M69: 0 | N69: 0 | P69: 60.4
A70: USR-100069 | B70: 45735 | C70: Control | D70: East | E70: Desktop | F70: Email | G70: Free | H70: 1 | I70: 1 | J70: 1 | K70: 0 | L70: 0 | M70: 0 | N70: 0 | P70: 55.3
A71: USR-100070 | B71: 45793 | C71: Control | D71: North | E71: Desktop | F71: Organic | G71: Free | H71: 0 | I71: 0 | J71: 0 | K71: 0 | L71: 0 | M71: 0 | N71: 0 | P71: 56.2
A72: USR-100071 | B72: 45724 | C72: Control | D72: West | E72: Mobile | F72: Email | G72: Free | H72: 0 | I72: 0 | J72: 0 | K72: 0 | L72: 0 | M72: 0 | N72: 0 | P72: 29.4
A73: USR-100072 | B73: 45724 | C73: Control | D73: East | E73: Mobile | F73: Email | G73: Free | H73: 1 | I73: 0 | J73: 0 | K73: 0 | L73: 0 | M73: 0 | N73: 0 | P73: 54.2
... A79: USR-100078 | B79: 45673 | C79: Control | D79: North | E79: Mobile | F79: Organic | G79: Free | H79: 0 | I79: 0 | J79: 0 | K79: 0 | L79: 0 | M79: 2 | N79: 0 | P79: 48.4
A80: USR-100079 | B80: 45708 | C80: Control | D80: West | E80: Desktop | F80: Organic | G80: Free | H80: 1 | I80: 1 | J80: 1 | K80: 1 | L80: 457.51 | M80: 0 | N80: 0 | O80: 7 | P80: 38
A81: USR-100080 | B81: 45798 | C81: Control | D81: East | E81: Mobile | F81: Social | G81: Free | H81: 1 | I81: 0 | J81: 0 | K81: 0 | L81: 0 | M81: 0 | N81: 0 | P81: 44.2
A82: USR-100081 | B82: 45785 | C82: Control | D82: South | E82: Mobile | F82: Organic | G82: Free | H82: 1 | I82: 1 | J82: 1 | K82: 0 | L82: 0 | M82: 0 | N82: 0 | P82: 81.2
A83: USR-100082 | B83: 45724 | C83: Control | D83: South | E83: Mobile | F83: Referral | G83: Free | H83: 1 | I83: 1 | J83: 0 | K83: 0 | L83: 0 | M83: 0 | N83: 0 | P83: 63.8
A84: USR-100083 | B84: 45748 | C84: Control | D84: South | E84: Desktop | F84: Email | G84: Free | H84: 0 | I84: 0 | J84: 0 | K84: 0 | L84: 0 | M84: 0 | N84: 0 | P84: 64.7
A85: USR-100084 | B85: 45719 | C85: Control | D85: West | E85: Mobile | F85: Social | G85: Basic | H85: 0 | I85: 0 | J85: 0 | K85: 0 | L85: 0 | M85: 0 | N85: 0 | P85: 60.4
A86: USR-100085 | B86: 45763 | C86: Control | D86: South | E86: Mobile | F86: Paid Search | G86: Free | H86: 0 | I86: 0 | J86: 0 | K86: 0 | L86: 0 | M86: 0 | N86: 0 | P86: 66.6
A87: USR-100086 | B87: 45666 | C87: Control | D87: North | E87: Desktop | F87: Organic | G87: Free | H87: 1 | I87: 0 | J87: 0 | K87: 0 | L87: 0 | M87: 0 | N87: 0 | P87: 50.9
A88: USR-100087 | B88: 45679 | C88: Control | D88: West | E88: Desktop | F88: Social | G88: Basic | H88: 0 | I88: 0 | J88: 0 | K88: 0 | L88: 0 | M88: 0 | N88: 0 | P88: 51
A89: USR-100088 | B89: 45777 | C89: Control | D89: South | E89: Mobile | F89: Email | G89: Premium | H89: 0 | I89: 0 | J89: 0 | K89: 0 | L89: 0 | M89: 0 | N89: 0 | P89: 65.8
A90: USR-100089 | B90: 45772 | C90: Control | D90: North | E90: Mobile | F90: Referral | G90: Basic | H90: 1 | I90: 0 | J90: 0 | K90: 0 | L90: 0 | M90: 0 | N90: 0 | P90: 61.8
A91: USR-100090 | B91: 45689 | C91: Control | D91: North | E91: Mobile | F91: Organic | G91: Basic | H91: 1 | I91: 0 | J91: 0 | K91: 0 | L91: 0 | M91: 0 | N91: 0 | P91: 54.5
...

Sheet Summary
A1: Experiment Summary — Control vs Treatment
A2: Onboarding & Activation Campaign Experiment
A4: Metric | B4: Required Calculation | C4: Control | D4: Treatment | E4: Abs. Difference | F4: Relative Lift
A5: User count | B5: Number of users in each group | C5: =COUNTIF(Cleaned_Data!C2:C1401,"Control") -> 690 | D5: =COUNTIF(Cleaned_Data!C2:C1401,"Treatment") -> 710 | E5: =D5-C5 -> 20 | F5: =IF(C5=0,"n/a",(D5-C5)/C5) -> 0.028985507
A6: Landing page visit rate | B6: Visited landing page / total users | C6: =AVERAGEIF(Cleaned_Data!C2:C1401,"Control",Cleaned_Data!H2:H1401) -> 0.63623188 | D6: =AVERAGEIF(Cleaned_Data!C2:C1401,"Treatment",Cleaned_Data!H2:H1401) -> 0.72394366 | E6: =D6-C6 -> 0.087711778 | F6: =IF(C6=0,"n/a",(D6-C6)/C6) -> 0.13786134
A7: Trial start rate | B7: Started trial / total users | C7: =AVERAGEIF(Cleaned_Data!C2:C1401,"Control",Cleaned_Data!I2:I1401) -> 0.25072464 | D7: =AVERAGEIF(Cleaned_Data!C2:C1401,"Treatment",Cleaned_Data!I2:I1401) -> 0.29014085 | E7: =D7-C7 -> 0.039416207 | F7: =IF(C7=0,"n/a",(D7-C7)/C7) -> 0.15720915
A8: Onboarding completion rate | B8: Completed onboarding / total users | C8: =AVERAGEIF(Cleaned_Data!C2:C1401,"Control",Cleaned_Data!J2:J1401) -> 0.15652174 | D8: =AVERAGEIF(Cleaned_Data!C2:C1401,"Treatment",Cleaned_Data!J2:J1401) -> 0.21126761 | E8: =D8-C8 -> 0.054745867 | F8: =IF(C8=0,"n/a",(D8-C8)/C8) -> 0.34976526
A9: Paid conversion rate (NORTH STAR) | B9: Converted to paid / total users | C9: =AVERAGEIF(Cleaned_Data!C2:C1401,"Control",Cleaned_Data!K2:K1401) -> 0.031884058 | D9: =AVERAGEIF(Cleaned_Data!C2:C1401,"Treatment",Cleaned_Data!K2:K1401) -> 0.070422535 | E9: =D9-C9 -> 0.038538477 | F9: =IF(C9=0,"n/a",(D9-C9)/C9) -> 1.2087068
A10: Average revenue per user | B10: Total revenue / total users | C10: =AVERAGEIF(Cleaned_Data!C2:C1401,"Control",Cleaned_Data!L2:L1401) -> 51.974319 | D10: =AVERAGEIF(Cleaned_Data!C2:C1401,"Treatment",Cleaned_Data!L2:L1401) -> 54.254521 | E10: =D10-C10 -> 2.2802023 | F10: =IF(C10=0,"n/a",(D10-C10)/C10) -> 0.043871711
A11: Average revenue per converted user | B11: Revenue / converted users | C11: =SUMIFS(Cleaned_Data!L2:L1401,Cleaned_Data!C2:C1401,"Control",Cleaned_Data!K2:K1401,1)/COUNTIFS(Cleaned_Data!C2:C1401,"Control",Cleaned_Data!K2:K1401,1) -> 1630.1036 | D11: =SUMIFS(Cleaned_Data!L2:L1401,Cleaned_Data!C2:C1401,"Treatment",Cleaned_Data!K2:K1401,1)/COUNTIFS(Cleaned_Data!C2:C1401,"Treatment",Cleaned_Data!K2:K1401,1) -> 770.4142 | E11: =D11-C11 -> -859.68944 | F11: =IF(C11=0,"n/a",(D11-C11)/C11) -> -0.5273833
A12: Refund rate | B12: Refund requests / total users | C12: =AVERAGEIF(Cleaned_Data!C2:C1401,"Control",Cleaned_Data!N2:N1401) -> 0 | D12: =AVERAGEIF(Cleaned_Data!C2:C1401,"Treatment",Cleaned_Data!N2:N1401) -> 0.0042253521 | E12: =D12-C12 -> 0.0042253521 | F12: =IF(C12=0,"n/a",(D12-C12)/C12) -> n/a
A13: Support ticket rate | B13: Users with support tickets / total users | C13: =COUNTIFS(Cleaned_Data!C2:C1401,"Control",Cleaned_Data!M2:M1401,">0")/COUNTIF(Cleaned_Data!C2:C1401,"Control") -> 0.14782609 | D13: =COUNTIFS(Cleaned_Data!C2:C1401,"Treatment",Cleaned_Data!M2:M1401,">0")/COUNTIF(Cleaned_Data!C2:C1401,"Treatment") -> 0.24788732 | E13: =D13-C13 -> 0.10006124 | F13: =IF(C13=0,"n/a",(D13-C13)/C13) -> 0.67688484
A14: Average engagement score | B14: Average score by group | C14: =AVERAGEIF(Cleaned_Data!C2:C1401,"Control",Cleaned_Data!P2:P1401) -> 57.029532 | D14: =AVERAGEIF(Cleaned_Data!C2:C1401,"Treatment",Cleaned_Data!P2:P1401) -> 62.940028 | E14: =D14-C14 -> 5.9104963 | F14: =IF(C14=0,"n/a",(D14-C14)/C14) -> 0.10363922
A15: Average days to convert | B15: Average days for users who converted | C15: =AVERAGEIFS(Cleaned_Data!O2:O1401,Cleaned_Data!C2:C1401,"Control",Cleaned_Data!K2:K1401,1) -> 8.8636364 | D15: =AVERAGEIFS(Cleaned_Data!O2:O1401,Cleaned_Data!C2:C1401,"Treatment",Cleaned_Data!K2:K1401,1) -> 6.4 | E15: =D15-C15 -> -2.4636364 | F15: =IF(C15=0,"n/a",(D15-C15)/C15) -> -0.27794872
A17: Notes:
A18: • "Support ticket rate" = share of users with 1+ support ticket (not average ticket count), consistent with "Users with support tickets" wording in the spec.
A19: • "Average days to convert" is computed only over users who converted (days_to_convert is undefined for non-converters).
A20: • All figures are formulas referencing the Cleaned_Data sheet in this workbook and will recalculate if source data changes.

Sheet Segment_Analysis
A1: Segment-Level Analysis — Control vs Treatment
A2: Metrics analyzed by segment: Paid conversion rate, Support ticket rate, Average engagement score, Refund rate
A4: By Region
A5: Segment Value | B5: Control n | C5: Treatment n | D5: Control Conv. Rate | E5: Treatment Conv. Rate | F5: Control Support Tkt Rate | G5: Treatment Support Tkt Rate
A6: East | B6: =COUNTIFS(Cleaned_Data!D2:D1401,A6,Cleaned_Data!C2:C1401,"Control") -> 157 | C6: =COUNTIFS(Cleaned_Data!D2:D1401,A6,Cleaned_Data!C2:C1401,"Treatment") -> 170 | D6: =AVERAGEIFS(Cleaned_Data!K2:K1401,Cleaned_Data!D2:D1401,A6,Cleaned_Data!C2:C1401,"Control") -> 0.025477707 | E6: =AVERAGEIFS(Cleaned_Data!K2:K1401,Cleaned_Data!D2:D1401,A6,Cleaned_Data!C2:C1401,"Treatment") -> 0.064705882 | F6: =COUNTIFS(Cleaned_Data!D2:D1401,A6,Cleaned_Data!C2:C1401,"Control",Cleaned_Data!M2:M1401,">0")/B6 -> 0.14012739 | G6: =COUNTIFS(Cleaned_Data!D2:D1401,A6,Cleaned_Data!C2:C1401,"Treatment",Cleaned_Data!M2:M1401,">0")/C6 -> 0.26470588
A7: North | B7: =COUNTIFS(Cleaned_Data!D2:D1401,A7,Cleaned_Data!C2:C1401,"Control") -> 201 | C7: =COUNTIFS(Cleaned_Data!D2:D1401,A7,Cleaned_Data!C2:C1401,"Treatment") -> 180 | D7: =AVERAGEIFS(Cleaned_Data!K2:K1401,Cleaned_Data!D2:D1401,A7,Cleaned_Data!C2:C1401,"Control") -> 0.034825871 | E7: =AVERAGEIFS(Cleaned_Data!K2:K1401,Cleaned_Data!D2:D1401,A7,Cleaned_Data!C2:C1401,"Treatment") -> 0.088888889 | F7: =COUNTIFS(Cleaned_Data!D2:D1401,A7,Cleaned_Data!C2:C1401,"Control",Cleaned_Data!M2:M1401,">0")/B7 -> 0.15422886 | G7: =COUNTIFS(Cleaned_Data!D2:D1401,A7,Cleaned_Data!C2:C1401,"Treatment",Cleaned_Data!M2:M1401,">0")/C7 -> 0.22777778
A8: South | B8: =COUNTIFS(Cleaned_Data!D2:D1401,A8,Cleaned_Data!C2:C1401,"Control") -> 184 | C8: =COUNTIFS(Cleaned_Data!D2:D1401,A8,Cleaned_Data!C2:C1401,"Treatment") -> 183 | D8: =AVERAGEIFS(Cleaned_Data!K2:K1401,Cleaned_Data!D2:D1401,A8,Cleaned_Data!C2:C1401,"Control") -> 0.032608696 | E8: =AVERAGEIFS(Cleaned_Data!K2:K1401,Cleaned_Data!D2:D1401,A8,Cleaned_Data!C2:C1401,"Treatment") -> 0.076502732 | F8: =COUNTIFS(Cleaned_Data!D2:D1401,A8,Cleaned_Data!C2:C1401,"Control",Cleaned_Data!M2:M1401,">0")/B8 -> 0.14130435 | G8: =COUNTIFS(Cleaned_Data!D2:D1401,A8,Cleaned_Data!C2:C1401,"Treatment",Cleaned_Data!M2:M1401,">0")/C8 -> 0.22404372
A9: West | B9: =COUNTIFS(Cleaned_Data!D2:D1401,A9,Cleaned_Data!C2:C1401,"Control") -> 148 | C9: =COUNTIFS(Cleaned_Data!D2:D1401,A9,Cleaned_Data!C2:C1401,"Treatment") -> 177 | D9: =AVERAGEIFS(Cleaned_Data!K2:K1401,Cleaned_Data!D2:D1401,A9,Cleaned_Data!C2:C1401,"Control") -> 0.033783784 | E9: =AVERAGEIFS(Cleaned_Data!K2:K1401,Cleaned_Data!D2:D1401,A9,Cleaned_Data!C2:C1401,"Treatment") -> 0.050847458 | F9: =COUNTIFS(Cleaned_Data!D2:D1401,A9,Cleaned_Data!C2:C1401,"Control",Cleaned_Data!M2:M1401,">0")/B9 -> 0.15540541 | G9: =COUNTIFS(Cleaned_Data!D2:D1401,A9,Cleaned_Data!C2:C1401,"Treatment",Cleaned_Data!M2:M1401,">0")/C9 -> 0.27683616
A11: By Device Type
A12: Segment Value | B12: Control n | C12: Treatment n | D12: Control Conv. Rate | E12: Treatment Conv. Rate | F12: Control Support Tkt Rate | G12: Treatment Support Tkt Rate
A13: Desktop | B13: =COUNTIFS(Cleaned_Data!E2:E1401,A13,Cleaned_Data!C2:C1401,"Control") -> 200 | C13: =COUNTIFS(Cleaned_Data!E2:E1401,A13,Cleaned_Data!C2:C1401,"Treatment") -> 213 | D13: =AVERAGEIFS(Cleaned_Data!K2:K1401,Cleaned_Data!E2:E1401,A13,Cleaned_Data!C2:C1401,"Control") -> 0.045 | E13: =AVERAGEIFS(Cleaned_Data!K2:K1401,Cleaned_Data!E2:E1401,A13,Cleaned_Data!C2:C1401,"Treatment") -> 0.0657277 | F13: =COUNTIFS(Cleaned_Data!E2:E1401,A13,Cleaned_Data!C2:C1401,"Control",Cleaned_Data!M2:M1401,">0")/B13 -> 0.15 | G13: =COUNTIFS(Cleaned_Data!E2:E1401,A13,Cleaned_Data!C2:C1401,"Treatment",Cleaned_Data!M2:M1401,">0")/C13 -> 0.23943662
A14: Mobile | B14: =COUNTIFS(Cleaned_Data!E2:E1401,A14,Cleaned_Data!C2:C1401,"Control") -> 426 | C14: =COUNTIFS(Cleaned_Data!E2:E1401,A14,Cleaned_Data!C2:C1401,"Treatment") -> 432 | D14: =AVERAGEIFS(Cleaned_Data!K2:K1401,Cleaned_Data!E2:E1401,A14,Cleaned_Data!C2:C1401,"Control") -> 0.025821596 | E14: =AVERAGEIFS(Cleaned_Data!K2:K1401,Cleaned_Data!E2:E1401,A14,Cleaned_Data!C2:C1401,"Treatment") -> 0.074074074 | F14: =COUNTIFS(Cleaned_Data!E2:E1401,A14,Cleaned_Data!C2:C1401,"Control",Cleaned_Data!M2:M1401,">0")/B14 -> 0.15258216 | G14: =COUNTIFS(Cleaned_Data!E2:E1401,A14,Cleaned_Data!C2:C1401,"Treatment",Cleaned_Data!M2:M1401,">0")/C14 -> 0.25231481
A15: Tablet | B15: =COUNTIFS(Cleaned_Data!E2:E1401,A15,Cleaned_Data!C2:C1401,"Control") -> 55 | C15: =COUNTIFS(Cleaned_Data!E2:E1401,A15,Cleaned_Data!C2:C1401,"Treatment") -> 56 | D15: =AVERAGEIFS(Cleaned_Data!K2:K1401,Cleaned_Data!E2:E1401,A15,Cleaned_Data!C2:C1401,"Control") -> 0.018181818 | E15: =AVERAGEIFS(Cleaned_Data!K2:K1401,Cleaned_Data!E2:E1401,A15,Cleaned_Data!C2:C1401,"Treatment") -> 0.071428571 | F15: =COUNTIFS(Cleaned_Data!E2:E1401,A15,Cleaned_Data!C2:C1401,"Control",Cleaned_Data!M2:M1401,">0")/B15 -> 0.10909091 | G15: =COUNTIFS(Cleaned_Data!E2:E1401,A15,Cleaned_Data!C2:C1401,"Treatment",Cleaned_Data!M2:M1401,">0")/C15 -> 0.21428571
A16: Unknown | B16: =COUNTIFS(Cleaned_Data!E2:E1401,A16,Cleaned_Data!C2:C1401,"Control") -> 9 | C16: =COUNTIFS(Cleaned_Data!E2:E1401,A16,Cleaned_Data!C2:C1401,"Treatment") -> 9 | D16: =AVERAGEIFS(Cleaned_Data!K2:K1401,Cleaned_Data!E2:E1401,A16,Cleaned_Data!C2:C1401,"Control") -> 0.11111111 | E16: =AVERAGEIFS(Cleaned_Data!K2:K1401,Cleaned_Data!E2:E1401,A16,Cleaned_Data!C2:C1401,"Treatment") -> 0 | F16: =COUNTIFS(Cleaned_Data!E2:E1401,A16,Cleaned_Data!C2:C1401,"Control",Cleaned_Data!M2:M1401,">0")/B16 -> 0.11111111 | G16: =COUNTIFS(Cleaned_Data!E2:E1401,A16,Cleaned_Data!C2:C1401,"Treatment",Cleaned_Data!M2:M1401,">0")/C16 -> 0.44444444
A18: By Traffic Source
A19: Segment Value | B19: Control n | C19: Treatment n | D19: Control Conv. Rate | E19: Treatment Conv. Rate | F19: Control Support Tkt Rate | G19: Treatment Support Tkt Rate
A20: Email | B20: =COUNTIFS(Cleaned_Data!F2:F1401,A20,Cleaned_Data!C2:C1401,"Control") -> 73 | C20: =COUNTIFS(Cleaned_Data!F2:F1401,A20,Cleaned_Data!C2:C1401,"Treatment") -> 56 | D20: =AVERAGEIFS(Cleaned_Data!K2:K1401,Cleaned_Data!F2:F1401,A20,Cleaned_Data!C2:C1401,"Control") -> 0.02739726 | E20: =AVERAGEIFS(Cleaned_Data!K2:K1401,Cleaned_Data!F2:F1401,A20,Cleaned_Data!C2:C1401,"Treatment") -> 0.071428571 | F20: =COUNTIFS(Cleaned_Data!F2:F1401,A20,Cleaned_Data!C2:C1401,"Control",Cleaned_Data!M2:M1401,">0")/B20 -> 0.16438356 | G20: =COUNTIFS(Cleaned_Data!F2:F1401,A20,Cleaned_Data!C2:C1401,"Treatment",Cleaned_Data!M2:M1401,">0")/C20 -> 0.33928571
A21: Organic | B21: =COUNTIFS(Cleaned_Data!F2:F1401,A21,Cleaned_Data!C2:C1401,"Control") -> 246 | C21: =COUNTIFS(Cleaned_Data!F2:F1401,A21,Cleaned_Data!C2:C1401,"Treatment") -> 237 | D21: =AVERAGEIFS(Cleaned_Data!K2:K1401,Cleaned_Data!F2:F1401,A21,Cleaned_Data!C2:C1401,"Control") -> 0.020325203 | E21: =AVERAGEIFS(Cleaned_Data!K2:K1401,Cleaned_Data!F2:F1401,A21,Cleaned_Data!C2:C1401,"Treatment") -> 0.063291139 | F21: =COUNTIFS(Cleaned_Data!F2:F1401,A21,Cleaned_Data!C2:C1401,"Control",Cleaned_Data!M2:M1401,">0")/B21 -> 0.12195122 | G21: =COUNTIFS(Cleaned_Data!F2:F1401,A21,Cleaned_Data!C2:C1401,"Treatment",Cleaned_Data!M2:M1401,">0")/C21 -> 0.2278481
A22: Paid Search | B22: =COUNTIFS(Cleaned_Data!F2:F1401,A22,Cleaned_Data!C2:C1401,"Control") -> 155 | C22: =COUNTIFS(Cleaned_Data!F2:F1401,A22,Cleaned_Data!C2:C1401,"Treatment") -> 176 | D22: =AVERAGEIFS(Cleaned_Data!K2:K1401,Cleaned_Data!F2:F1401,A22,Cleaned_Data!C2:C1401,"Control") -> 0.012903226 | E22: =AVERAGEIFS(Cleaned_Data!K2:K1401,Cleaned_Data!F2:F1401,A22,Cleaned_Data!C2:C1401,"Treatment") -> 0.0625 | F22: =COUNTIFS(Cleaned_Data!F2:F1401,A22,Cleaned_Data!C2:C1401,"Control",Cleaned_Data!M2:M1401,">0")/B22 -> 0.18709677 | G22: =COUNTIFS(Cleaned_Data!F2:F1401,A22,Cleaned_Data!C2:C1401,"Treatment",Cleaned_Data!M2:M1401,">0")/C22 -> 0.22159091
A23: Referral | B23: =COUNTIFS(Cleaned_Data!F2:F1401,A23,Cleaned_Data!C2:C1401,"Control") -> 81 | C23: =COUNTIFS(Cleaned_Data!F2:F1401,A23,Cleaned_Data!C2:C1401,"Treatment") -> 91 | D23: =AVERAGEIFS(Cleaned_Data!K2:K1401,Cleaned_Data!F2:F1401,A23,Cleaned_Data!C2:C1401,"Control") -> 0.024691358 | E23: =AVERAGEIFS(Cleaned_Data!K2:K1401,Cleaned_Data!F2:F1401,A23,Cleaned_Data!C2:C1401,"Treatment") -> 0.10989011 | F23: =COUNTIFS(Cleaned_Data!F2:F1401,A23,Cleaned_Data!C2:C1401,"Control",Cleaned_Data!M2:M1401,">0")/B23 -> 0.12345679 | G23: =COUNTIFS(Cleaned_Data!F2:F1401,A23,Cleaned_Data!C2:C1401,"Treatment",Cleaned_Data!M2:M1401,">0")/C23 -> 0.28571429
A24: Social | B24: =COUNTIFS(Cleaned_Data!F2:F1401,A24,Cleaned_Data!C2:C1401,"Control") -> 129 | C24: =COUNTIFS(Cleaned_Data!F2:F1401,A24,Cleaned_Data!C2:C1401,"Treatment") -> 132 | D24: =AVERAGEIFS(Cleaned_Data!K2:K1401,Cleaned_Data!F2:F1401,A24,Cleaned_Data!C2:C1401,"Control") -> 0.07751938 | E24: =AVERAGEIFS(Cleaned_Data!K2:K1401,Cleaned_Data!F2:F1401,A24,Cleaned_Data!C2:C1401,"Treatment") -> 0.060606061 | F24: =COUNTIFS(Cleaned_Data!F2:F1401,A24,Cleaned_Data!C2:C1401,"Control",Cleaned_Data!M2:M1401,">0")/B24 -> 0.14728682 | G24: =COUNTIFS(Cleaned_Data!F2:F1401,A24,Cleaned_Data!C2:C1401,"Treatment",Cleaned_Data!M2:M1401,">0")/C24 -> 0.27272727
A25: Unknown | B25: =COUNTIFS(Cleaned_Data!F2:F1401,A25,Cleaned_Data!C2:C1401,"Control") -> 6 | C25: =COUNTIFS(Cleaned_Data!F2:F1401,A25,Cleaned_Data!C2:C1401,"Treatment") -> 18 | D25: =AVERAGEIFS(Cleaned_Data!K2:K1401,Cleaned_Data!F2:F1401,A25,Cleaned_Data!C2:C1401,"Control") -> 0.16666667 | E25: =AVERAGEIFS(Cleaned_Data!K2:K1401,Cleaned_Data!F2:F1401,A25,Cleaned_Data!C2:C1401,"Treatment") -> 0.11111111 | F25: =COUNTIFS(Cleaned_Data!F2:F1401,A25,Cleaned_Data!C2:C1401,"Control",Cleaned_Data!M2:M1401,">0")/B25 -> 0.33333333 | G25: =COUNTIFS(Cleaned_Data!F2:F1401,A25,Cleaned_Data!C2:C1401,"Treatment",Cleaned_Data!M2:M1401,">0")/C25 -> 0.11111111
A27: By Plan Type
A28: Segment Value | B28: Control n | C28: Treatment n | D28: Control Conv. Rate | E28: Treatment Conv. Rate | F28: Control Support Tkt Rate | G28: Treatment Support Tkt Rate
A29: Basic | B29: =COUNTIFS(Cleaned_Data!G2:G1401,A29,Cleaned_Data!C2:C1401,"Control") -> 221 | C29: =COUNTIFS(Cleaned_Data!G2:G1401,A29,Cleaned_Data!C2:C1401,"Treatment") -> 232 | D29: =AVERAGEIFS(Cleaned_Data!K2:K1401,Cleaned_Data!G2:G1401,A29,Cleaned_Data!C2:C1401,"Control") -> 0.036199095 | E29: =AVERAGEIFS(Cleaned_Data!K2:K1401,Cleaned_Data!G2:G1401,A29,Cleaned_Data!C2:C1401,"Treatment") -> 0.038793103 | F29: =COUNTIFS(Cleaned_Data!G2:G1401,A29,Cleaned_Data!C2:C1401,"Control",Cleaned_Data!M2:M1401,">0")/B29 -> 0.14479638 | G29: =COUNTIFS(Cleaned_Data!G2:G1401,A29,Cleaned_Data!C2:C1401,"Treatment",Cleaned_Data!M2:M1401,">0")/C29 -> 0.25
A30: Free | B30: =COUNTIFS(Cleaned_Data!G2:G1401,A30,Cleaned_Data!C2:C1401,"Control") -> 360 | C30: =COUNTIFS(Cleaned_Data!G2:G1401,A30,Cleaned_Data!C2:C1401,"Treatment") -> 366 | D30: =AVERAGEIFS(Cleaned_Data!K2:K1401,Cleaned_Data!G2:G1401,A30,Cleaned_Data!C2:C1401,"Control") -> 0.030555556 | E30: =AVERAGEIFS(Cleaned_Data!K2:K1401,Cleaned_Data!G2:G1401,A30,Cleaned_Data!C2:C1401,"Treatment") -> 0.092896175 | F30: =COUNTIFS(Cleaned_Data!G2:G1401,A30,Cleaned_Data!C2:C1401,"Control",Cleaned_Data!M2:M1401,">0")/B30 -> 0.12222222 | G30: =COUNTIFS(Cleaned_Data!G2:G1401,A30,Cleaned_Data!C2:C1401,"Treatment",Cleaned_Data!M2:M1401,">0")/C30 -> 0.24043716
A31: Premium | B31: =COUNTIFS(Cleaned_Data!G2:G1401,A31,Cleaned_Data!C2:C1401,"Control") -> 109 | C31: =COUNTIFS(Cleaned_Data!G2:G1401,A31,Cleaned_Data!C2:C1401,"Treatment") -> 112 | D31: =AVERAGEIFS(Cleaned_Data!K2:K1401,Cleaned_Data!G2:G1401,A31,Cleaned_Data!C2:C1401,"Control") -> 0.027522936 | E31: =AVERAGEIFS(Cleaned_Data!K2:K1401,Cleaned_Data!G2:G1401,A31,Cleaned_Data!C2:C1401,"Treatment") -> 0.0625 | F31: =COUNTIFS(Cleaned_Data!G2:G1401,A31,Cleaned_Data!C2:C1401,"Control",Cleaned_Data!M2:M1401,">0")/B31 -> 0.23853211 | G31: =COUNTIFS(Cleaned_Data!G2:G1401,A31,Cleaned_Data!C2:C1401,"Treatment",Cleaned_Data!M2:M1401,">0")/C31 -> 0.26785714
A33: By Region — Engagement Score & Refund Rate (additional guardrail view)
A34: Region | B34: Control n | C34: Treatment n | D34: Control Avg. Engagement | E34: Treatment Avg. Engagement | F34: Control Refund Rate | G34: Treatment Refund Rate
A35: East | B35: =COUNTIFS(Cleaned_Data!D2:D1401,A35,Cleaned_Data!C2:C1401,"Control") -> 157 | C35: =COUNTIFS(Cleaned_Data!D2:D1401,A35,Cleaned_Data!C2:C1401,"Treatment") -> 170 | D35: =AVERAGEIFS(Cleaned_Data!P2:P1401,Cleaned_Data!D2:D1401,A35,Cleaned_Data!C2:C1401,"Control") -> 56.556051 | E35: =AVERAGEIFS(Cleaned_Data!P2:P1401,Cleaned_Data!D2:D1401,A35,Cleaned_Data!C2:C1401,"Treatment") -> 63.307692 | F35: =AVERAGEIFS(Cleaned_Data!N2:N1401,Cleaned_Data!D2:D1401,A35,Cleaned_Data!C2:C1401,"Control") -> 0 | G35: =AVERAGEIFS(Cleaned_Data!N2:N1401,Cleaned_Data!D2:D1401,A35,Cleaned_Data!C2:C1401,"Treatment") -> 0.0058823529
A36: North | B36: =COUNTIFS(Cleaned_Data!D2:D1401,A36,Cleaned_Data!C2:C1401,"Control") -> 201 | C36: =COUNTIFS(Cleaned_Data!D2:D1401,A36,Cleaned_Data!C2:C1401,"Treatment") -> 180 | D36: =AVERAGEIFS(Cleaned_Data!P2:P1401,Cleaned_Data!D2:D1401,A36,Cleaned_Data!C2:C1401,"Control") -> 57.616667 | E36: =AVERAGEIFS(Cleaned_Data!P2:P1401,Cleaned_Data!D2:D1401,A36,Cleaned_Data!C2:C1401,"Treatment") -> 63.153977 | F36: =AVERAGEIFS(Cleaned_Data!N2:N1401,Cleaned_Data!D2:D1401,A36,Cleaned_Data!C2:C1401,"Control") -> 0 | G36: =AVERAGEIFS(Cleaned_Data!N2:N1401,Cleaned_Data!D2:D1401,A36,Cleaned_Data!C2:C1401,"Treatment") -> 0
A37: South | B37: =COUNTIFS(Cleaned_Data!D2:D1401,A37,Cleaned_Data!C2:C1401,"Control") -> 184 | C37: =COUNTIFS(Cleaned_Data!D2:D1401,A37,Cleaned_Data!C2:C1401,"Treatment") -> 183 | D37: =AVERAGEIFS(Cleaned_Data!P2:P1401,Cleaned_Data!D2:D1401,A37,Cleaned_Data!C2:C1401,"Control") -> 56.904972 | E37: =AVERAGEIFS(Cleaned_Data!P2:P1401,Cleaned_Data!D2:D1401,A37,Cleaned_Data!C2:C1401,"Treatment") -> 62.11326 | F37: =AVERAGEIFS(Cleaned_Data!N2:N1401,Cleaned_Data!D2:D1401,A37,Cleaned_Data!C2:C1401,"Control") -> 0 | G37: =AVERAGEIFS(Cleaned_Data!N2:N1401,Cleaned_Data!D2:D1401,A37,Cleaned_Data!C2:C1401,"Treatment") -> 0
A38: West | B38: =COUNTIFS(Cleaned_Data!D2:D1401,A38,Cleaned_Data!C2:C1401,"Control") -> 148 | C38: =COUNTIFS(Cleaned_Data!D2:D1401,A38,Cleaned_Data!C2:C1401,"Treatment") -> 177 | D38: =AVERAGEIFS(Cleaned_Data!P2:P1401,Cleaned_Data!D2:D1401,A38,Cleaned_Data!C2:C1401,"Control") -> 56.898649 | E38: =AVERAGEIFS(Cleaned_Data!P2:P1401,Cleaned_Data!D2:D1401,A38,Cleaned_Data!C2:C1401,"Treatment") -> 63.223295 | F38: =AVERAGEIFS(Cleaned_Data!N2:N1401,Cleaned_Data!D2:D1401,A38,Cleaned_Data!C2:C1401,"Control") -> 0 | G38: =AVERAGEIFS(Cleaned_Data!N2:N1401,Cleaned_Data!D2:D1401,A38,Cleaned_Data!C2:C1401,"Treatment") -> 0.011299435

Sheet Hypothesis_Test
A1: Hypothesis Test — Two-Proportion Z-Test on Paid Conversion Rate
A2: Primary metric: Paid conversion rate (North Star)
A4: 1. Test Setup
A6: Test type | C6: Two-proportion z-test (one-tailed)
A7: Metric tested | C7: Paid conversion rate (converted_to_paid)
A8: H0 (null) | C8: p_treatment = p_control
A9: H1 (alternate) | C9: p_treatment > p_control
A10: Significance level (alpha) | C10: 0.05 | D10: Input — change to re-run the test at a different threshold
A12: 2. Inputs (from Cleaned_Data)
A14: n (Control) | C14: =COUNTIF(Cleaned_Data!C2:C1401,"Control") -> 690
A15: n (Treatment) | C15: =COUNTIF(Cleaned_Data!C2:C1401,"Treatment") -> 710
A16: Conversions (Control) | C16: =COUNTIFS(Cleaned_Data!C2:C1401,"Control",Cleaned_Data!K2:K1401,1) -> 22
A17: Conversions (Treatment) | C17: =COUNTIFS(Cleaned_Data!C2:C1401,"Treatment",Cleaned_Data!K2:K1401,1) -> 50
A19: 3. Calculation
A21: p1 = Control conversion rate | C21: =C16/C14 -> 0.031884058
A22: p2 = Treatment conversion rate | C22: =C17/C15 -> 0.070422535
A23: Pooled proportion (p_pool) | C23: =(C16+C17)/(C14+C15) -> 0.051428571
A24: Standard error (SE) | C24: =SQRT(C23*(1-C23)*(1/C14+1/C15)) -> 0.011807217
A25: Z-statistic | C25: =(C22-C21)/C24 -> 3.2639763
A26: P-value (one-tailed) | C26: =1-_xlfn.NORM.S.DIST(C25,TRUE()) -> 0.00054930169
A27: P-value (two-tailed, reference) | C27: =2*(1-_xlfn.NORM.S.DIST(ABS(C25),TRUE())) -> 0.0010986034
A28: Observed difference (p2 - p1) | C28: =C22-C21 -> 0.038538477
A29: 95% CI lower bound | C29: =(C22-C21)-1.96*SQRT((C21*(1-C21))/C14+(C22*(1-C22))/C15) -> 0.015602528
A30: 95% CI upper bound | C30: =(C22-C21)+1.96*SQRT((C21*(1-C21))/C14+(C22*(1-C22))/C15) -> 0.061474426
A31: Relative lift | C31: =(C22-C21)/C21 -> 1.2087068
A33: 4. Decision & Interpretation
A35: Decision | C35: =IF(C26<C10,"REJECT H0 — statistically significant improvement","FAIL TO REJECT H0 — no significant improvement") -> REJECT H0 — statistically significant improvement
A37: ="With "&TEXT(C14,"#,##0")&" Control and "&TEXT(C15,"#,##0")&" Treatment users, conversion rose from "&TEXT(C21,"0.00%")&" to "&TEXT(C22,"0.00%")&" (z = "&TEXT(C25,"0.00")&", one-tailed p = "&TEXT(C26,"0.0000")&"). The result is statistically significant at the "&TEXT(C10,"0%")&" level: the treatment effect on paid conversion is very unlikely to be due to random chance." -> With 690 Control and 710 Treatment users, conversion rose from 3.19% to 7.04% (z = 3.26, one-tailed p = 0.0005). The result is statistically significant at the 5% level: the treatment effect on paid conversion is very unlikely to be due to random chance.
