Workbook

Sheet Raw_Data
A1: user_id | B1: signup_date | C1: experiment_group | D1: region | E1: device_type | F1: traffic_source | G1: plan_type | H1: visited_landing_page | I1: started_trial | J1: completed_onboarding | K1: converted_to_paid | L1: revenue_30d | M1: support_tickets_30d | N1: refund_requested | O1: days_to_convert | P1: engagement_score
A2: USR-100001 | B2: 45732 | C2: Control | D2: North | E2: Desktop | F2: Email | G2: Basic | H2: 0 | I2: 0 | J2: 0 | K2: 0 | L2: 0 | M2: 0 | N2: 0 | P2: 45.7
A3: USR-100002 | B3: 45724 | C3: Control | D3: West | E3: Mobile | F3: Organic | G3: Free | H3: 1 | I3: 0 | J3: 0 | K3: 0 | L3: 0 | M3: 0 | N3: 0 | P3: 48.6
A4: USR-100003 | B4: 45771 | C4: Control | D4: East | E4: Mobile | F4: Paid Search | G4: Premium | H4: 1 | I4: 0 | J4: 0 | K4: 0 | L4: 0 | M4: 1 | N4: 0 | P4: 35.4
A5: USR-100004 | B5: 45781 | C5: Control | D5: South | E5: Mobile | F5: Email | G5: Basic | H5: 1 | I5: 0 | J5: 0 | K5: 0 | L5: 0 | M5: 0 | N5: 0 | P5: 64.6
A6: USR-100005 | B6: 45700 | C6: Control | D6: North | E6: Tablet | F6: Organic | G6: Free | H6: 0 | I6: 0 | J6: 0 | K6: 0 | L6: 0 | M6: 0 | N6: 0 | P6: 66.6
A7: USR-100006 | B7: 45685 | C7: Control | D7: East | E7: Mobile | F7: Organic | G7: Premium | H7: 1 | I7: 0 | J7: 0 | K7: 0 | L7: 0 | M7: 0 | N7: 0 | P7: 40.8
A8: USR-100007 | B8: 45755 | C8: Control | D8: East | E8: Mobile | F8: Paid Search | G8: Basic | H8: 1 | I8: 1 | J8: 0 | K8: 0 | L8: 0 | M8: 0 | N8: 0 | P8: 57.1
A9: USR-100008 | B9: 45794 | C9: Control | D9: South | E9: Mobile | F9: Paid Search | G9: Free | H9: 0 | I9: 0 | J9: 0 | K9: 0 | L9: 0 | M9: 0 | N9: 0 | P9: 36.4
A10: USR-100009 | B10: 45711 | C10: Control | D10: South | E10: Tablet | F10: Referral | G10: Basic | H10: 0 | I10: 0 | J10: 0 | K10: 0 | L10: 0 | M10: 0 | N10: 0 | P10: 55.4
A11: USR-100010 | B11: 45806 | C11: Control | D11: West | E11: Desktop | F11: Social | G11: Free | H11: 1 | I11: 0 | J11: 0 | K11: 0 | L11: 0 | M11: 0 | N11: 0 | P11: 57.3
A12: USR-100011 | B12: 45777 | C12: Control | D12: East | E12: Mobile | F12: Paid Search | G12: Basic | H12: 1 | I12: 1 | J12: 1 | K12: 0 | L12: 0 | M12: 0 | N12: 0 | P12: 63.6
A13: USR-100012 | B13: 45732 | C13: Control | D13: East | E13: Mobile | F13: Social | G13: Premium | H13: 1 | I13: 1 | J13: 1 | K13: 0 | L13: 0 | M13: 1 | N13: 0 | P13: 80.4
... A60: USR-100059 | B60: 45761 | C60: Control | D60: North | E60: Mobile | F60: Social | G60: Free | H60: 0 | I60: 0 | J60: 0 | K60: 0 | L60: 0 | M60: 2 | N60: 0 | P60: 48.9
A61: USR-100060 | B61: 45658 | C61: Control | D61: West | E61: Mobile | F61: Social | G61: Free | H61: 1 | I61: 1 | J61: 1 | K61: 1 | L61: 240.42 | M61: 0 | N61: 0 | O61: 16 | P61: 56.5
A62: USR-100061 | B62: 45749 | C62: Control | D62: South | E62: Mobile | F62: Referral | G62: Free | H62: 1 | I62: 0 | J62: 0 | K62: 0 | L62: 0 | M62: 0 | N62: 0 | P62: 53.7
A63: USR-100062 | B63: 45745 | C63: Control | D63: North | E63: Mobile | F63: Social | G63: Premium | H63: 0 | I63: 0 | J63: 0 | K63: 0 | L63: 0 | M63: 0 | N63: 0 | P63: 62.2
A64: USR-100063 | B64: 45792 | C64: Control | D64: South | E64: Desktop | F64: Organic | G64: Free | H64: 1 | I64: 0 | J64: 0 | K64: 0 | L64: 0 | M64: 0 | N64: 0 | P64: 50.2
A65: USR-100064 | B65: 45758 | C65: Control | D65: North | E65: Mobile | F65: Organic | G65: Basic | H65: 1 | I65: 0 | J65: 0 | K65: 0 | L65: 0 | M65: 0 | N65: 0 | P65: 74.3
A66: USR-100065 | B66: 45723 | C66: Control | D66: South | E66: Desktop | F66: Paid Search | G66: Free | H66: 1 | I66: 0 | J66: 0 | K66: 0 | L66: 0 | M66: 0 | N66: 0 | P66: 58
A67: USR-100066 | B67: 45807 | C67: Control | D67: South | E67: Mobile | F67: Organic | G67: Free | H67: 0 | I67: 0 | J67: 0 | K67: 0 | L67: 0 | M67: 0 | N67: 0 | P67: 46.7
A68: USR-100067 | B68: 45664 | C68: Control | D68: South | E68: Desktop | F68: Organic | G68: Premium | H68: 1 | I68: 0 | J68: 0 | K68: 0 | L68: 0 | M68: 1 | N68: 0 | P68: 49.6
A69: USR-100068 | B69: 45785 | C69: Control | D69: West | E69: Mobile | F69: Social | G69: Free | H69: 0 | I69: 0 | J69: 0 | K69: 0 | L69: 0 | M69: 0 | N69: 0 | P69: 60.4
A70: USR-100069 | B70: 45735 | C70: Control | D70: East | E70: Desktop | F70: Email | G70: Free | H70: 1 | I70: 1 | J70: 1 | K70: 0 | L70: 0 | M70: 0 | N70: 0 | P70: 55.3
A71: USR-100070 | B71: 45793 | C71: Control | D71: North | E71: Desktop | F71: Organic | G71: Free | H71: 0 | I71: 0 | J71: 0 | K71: 0 | L71: 0 | M71: 0 | N71: 0 | P71: 56.2
A72: USR-100071 | B72: 45724 | C72: Control | D72: West | E72: Mobile | F72: Email | G72: Free | H72: 0 | I72: 0 | J72: 0 | K72: 0 | L72: 0 | M72: 0 | N72: 0 | P72: 29.4
A73: USR-100072 | B73: 45724 | C73: Control | D73: East | E73: Mobile | F73: Email | G73: Free | H73: 1 | I73: 0 | J73: 0 | K73: 0 | L73: 0 | M73: 0 | N73: 0 | P73: 54.2
... A79: USR-100078 | B79: 45673 | C79: Control | D79: North | E79: Mobile | F79: Organic | G79: Free | H79: 0 | I79: 0 | J79: 0 | K79: 0 | L79: 0 | M79: 2 | N79: 0 | P79: 48.4
A80: USR-100079 | B80: 45708 | C80: Control | D80: West | E80: Desktop | F80: Organic | G80: Free | H80: 1 | I80: 1 | J80: 1 | K80: 1 | L80: 457.51 | M80: 0 | N80: 0 | O80: 7 | P80: 38
A81: USR-100080 | B81: 45798 | C81: Control | D81: East | E81: Mobile | F81: Social | G81: Free | H81: 1 | I81: 0 | J81: 0 | K81: 0 | L81: 0 | M81: 0 | N81: 0 | P81: 44.2
A82: USR-100081 | B82: 45785 | C82: Control | D82: South | E82: Mobile | F82: Organic | G82: Free | H82: 1 | I82: 1 | J82: 1 | K82: 0 | L82: 0 | M82: 0 | N82: 0 | P82: 81.2
A83: USR-100082 | B83: 45724 | C83: Control | D83: South | E83: Mobile | F83: Referral | G83: Free | H83: 1 | I83: 1 | J83: 0 | K83: 0 | L83: 0 | M83: 0 | N83: 0 | P83: 63.8
A84: USR-100083 | B84: 45748 | C84: Control | D84: South | E84: Desktop | F84: Email | G84: Free | H84: 0 | I84: 0 | J84: 0 | K84: 0 | L84: 0 | M84: 0 | N84: 0 | P84: 64.7
A85: USR-100084 | B85: 45719 | C85: Control | D85: West | E85: Mobile | F85: Social | G85: Basic | H85: 0 | I85: 0 | J85: 0 | K85: 0 | L85: 0 | M85: 0 | N85: 0 | P85: 60.4
A86: USR-100085 | B86: 45763 | C86: Control | D86: South | E86: Mobile | F86: Paid Search | G86: Free | H86: 0 | I86: 0 | J86: 0 | K86: 0 | L86: 0 | M86: 0 | N86: 0 | P86: 66.6
A87: USR-100086 | B87: 45666 | C87: Control | D87: North | E87: Desktop | F87: Organic | G87: Free | H87: 1 | I87: 0 | J87: 0 | K87: 0 | L87: 0 | M87: 0 | N87: 0 | P87: 50.9
A88: USR-100087 | B88: 45679 | C88: Control | D88: West | E88: Desktop | F88: Social | G88: Basic | H88: 0 | I88: 0 | J88: 0 | K88: 0 | L88: 0 | M88: 0 | N88: 0 | P88: 51
A89: USR-100088 | B89: 45777 | C89: Control | D89: South | E89: Mobile | F89: Email | G89: Premium | H89: 0 | I89: 0 | J89: 0 | K89: 0 | L89: 0 | M89: 0 | N89: 0 | P89: 65.8
A90: USR-100089 | B90: 45772 | C90: Control | D90: North | E90: Mobile | F90: Referral | G90: Basic | H90: 1 | I90: 0 | J90: 0 | K90: 0 | L90: 0 | M90: 0 | N90: 0 | P90: 61.8
A91: USR-100090 | B91: 45689 | C91: Control | D91: North | E91: Mobile | F91: Organic | G91: Basic | H91: 1 | I91: 0 | J91: 0 | K91: 0 | L91: 0 | M91: 0 | N91: 0 | P91: 54.5
...

Sheet Data_Quality_Checks
A1: Data Quality Checks — campaign_experiment_data.xlsx
A3: 1. Dataset Size & Group Counts
A5: Total rows in raw data | D5: =COUNTA(Raw_Data!A2:A1409) -> 1408
A6: Control group count | D6: =COUNTIF(Raw_Data!C2:C1409,"Control") -> 693
A7: Treatment group count | D7: =COUNTIF(Raw_Data!C2:C1409,"Treatment") -> 715
A8: Group split check (Control+Treatment = Total) | D8: =D6+D7=D5 -> TRUE | E8: TRUE means groups reconcile to total rows (no unassigned/mislabeled group values)
A10: 2. Missing Values by Column
A12: Missing values — device_type | D12: =COUNTBLANK(Raw_Data!E2:E1409) -> 18
A13: Missing values — traffic_source | D13: =COUNTBLANK(Raw_Data!F2:F1409) -> 24
A14: Missing values — engagement_score | D14: =COUNTBLANK(Raw_Data!P2:P1409) -> 14
A15: Missing values — days_to_convert | D15: =COUNTBLANK(Raw_Data!O2:O1409) -> 1336 | E15: Expected: only populated for converted users (non-converters never had a conversion date)
A16: Missing values — region | D16: =COUNTBLANK(Raw_Data!D2:D1409) -> 0
A17: Missing values — plan_type | D17: =COUNTBLANK(Raw_Data!G2:G1409) -> 0
A18: Missing values — user_id | D18: =COUNTBLANK(Raw_Data!A2:A1409) -> 0
A19: Missing values — experiment_group | D19: =COUNTBLANK(Raw_Data!C2:C1409) -> 0
A20: Missing values — revenue_30d | D20: =COUNTBLANK(Raw_Data!L2:L1409) -> 0
A21: Missing values — support_tickets_30d | D21: =COUNTBLANK(Raw_Data!M2:M1409) -> 0
A22: Missing values — refund_requested | D22: =COUNTBLANK(Raw_Data!N2:N1409) -> 0
A24: 3. Duplicate User IDs
A26: Unique user IDs | D26: =SUMPRODUCT(1/COUNTIF(Raw_Data!A2:A1409,Raw_Data!A2:A1409)) -> 1400
A27: Duplicate user ID rows (extra occurrences beyond 1st) | D27: =COUNTA(Raw_Data!A2:A1409)-D26 -> 8 | E27: Total rows minus unique IDs = number of duplicate-row occurrences
A29: 4. Invalid Binary / Numeric Values
A31: Invalid (non 0/1) values — visited_landing_page | D31: =SUMPRODUCT((Raw_Data!H2:H1409<>0)*(Raw_Data!H2:H1409<>1)) -> 0
A32: Invalid (non 0/1) values — started_trial | D32: =SUMPRODUCT((Raw_Data!I2:I1409<>0)*(Raw_Data!I2:I1409<>1)) -> 0
A33: Invalid (non 0/1) values — completed_onboarding | D33: =SUMPRODUCT((Raw_Data!J2:J1409<>0)*(Raw_Data!J2:J1409<>1)) -> 0
A34: Invalid (non 0/1) values — converted_to_paid | D34: =SUMPRODUCT((Raw_Data!K2:K1409<>0)*(Raw_Data!K2:K1409<>1)) -> 0
A35: Invalid (non 0/1) values — refund_requested | D35: =SUMPRODUCT((Raw_Data!N2:N1409<>0)*(Raw_Data!N2:N1409<>1)) -> 0
A36: Negative values — support_tickets_30d | D36: =COUNTIF(Raw_Data!M2:M1409,"<0") -> 0
A37: Negative values — revenue_30d | D37: =COUNTIF(Raw_Data!L2:L1409,"<0") -> 0
A39: 5. Outliers — revenue_30d (z-score method, |z| > 3)
A41: Mean revenue_30d | D41: =AVERAGE(Raw_Data!L2:L1409) -> 52.828828
A42: Std dev revenue_30d | D42: =STDEV(Raw_Data!L2:L1409) -> 375.9367
A43: Outlier count (|z|>3) | D43: =SUMPRODUCT((ABS((Raw_Data!L2:L1409-D41)/D42)>3)*1) -> 18 | E43: High-revenue outliers are legitimate paid conversions, not data errors — retained but flagged for awareness in revenue-based averages
A44: Max revenue_30d | D44: =MAX(Raw_Data!L2:L1409) -> 8610.72
A45: Median revenue_30d | D45: =MEDIAN(Raw_Data!L2:L1409) -> 0
A47: 6. Segment Distribution Across Groups (Control vs Treatment)
A49: Segment | B49: Value | C49: Control % | D49: Treatment %
A50: region | B50: East | C50: =COUNTIFS(Raw_Data!D2:D1409,B50,Raw_Data!C2:C1409,"Control")/COUNTIF(Raw_Data!C2:C1409,"Control") -> 0.22799423 | D50: =COUNTIFS(Raw_Data!D2:D1409,B50,Raw_Data!C2:C1409,"Treatment")/COUNTIF(Raw_Data!C2:C1409,"Treatment") -> 0.24055944
A51: region | B51: North | C51: =COUNTIFS(Raw_Data!D2:D1409,B51,Raw_Data!C2:C1409,"Control")/COUNTIF(Raw_Data!C2:C1409,"Control") -> 0.29292929 | D51: =COUNTIFS(Raw_Data!D2:D1409,B51,Raw_Data!C2:C1409,"Treatment")/COUNTIF(Raw_Data!C2:C1409,"Treatment") -> 0.25174825
A52: region | B52: South | C52: =COUNTIFS(Raw_Data!D2:D1409,B52,Raw_Data!C2:C1409,"Control")/COUNTIF(Raw_Data!C2:C1409,"Control") -> 0.26551227 | D52: =COUNTIFS(Raw_Data!D2:D1409,B52,Raw_Data!C2:C1409,"Treatment")/COUNTIF(Raw_Data!C2:C1409,"Treatment") -> 0.25734266
...

Sheet Cleaned_Data
A1: user_id | B1: signup_date | C1: experiment_group | D1: region | E1: device_type | F1: traffic_source | G1: plan_type | H1: visited_landing_page | I1: started_trial | J1: completed_onboarding | K1: converted_to_paid | L1: revenue_30d | M1: support_tickets_30d | N1: refund_requested | O1: days_to_convert | P1: engagement_score
A2: USR-100001 | B2: 45732 | C2: Control | D2: North | E2: Desktop | F2: Email | G2: Basic | H2: 0 | I2: 0 | J2: 0 | K2: 0 | L2: 0 | M2: 0 | N2: 0 | P2: 45.7
A3: USR-100002 | B3: 45724 | C3: Control | D3: West | E3: Mobile | F3: Organic | G3: Free | H3: 1 | I3: 0 | J3: 0 | K3: 0 | L3: 0 | M3: 0 | N3: 0 | P3: 48.6
A4: USR-100003 | B4: 45771 | C4: Control | D4: East | E4: Mobile | F4: Paid Search | G4: Premium | H4: 1 | I4: 0 | J4: 0 | K4: 0 | L4: 0 | M4: 1 | N4: 0 | P4: 35.4
A5: USR-100004 | B5: 45781 | C5: Control | D5: South | E5: Mobile | F5: Email | G5: Basic | H5: 1 | I5: 0 | J5: 0 | K5: 0 | L5: 0 | M5: 0 | N5: 0 | P5: 64.6
A6: USR-100005 | B6: 45700 | C6: Control | D6: North | E6: Tablet | F6: Organic | G6: Free | H6: 0 | I6: 0 | J6: 0 | K6: 0 | L6: 0 | M6: 0 | N6: 0 | P6: 66.6
A7: USR-100006 | B7: 45685 | C7: Control | D7: East | E7: Mobile | F7: Organic | G7: Premium | H7: 1 | I7: 0 | J7: 0 | K7: 0 | L7: 0 | M7: 0 | N7: 0 | P7: 40.8
A8: USR-100007 | B8: 45755 | C8: Control | D8: East | E8: Mobile | F8: Paid Search | G8: Basic | H8: 1 | I8: 1 | J8: 0 | K8: 0 | L8: 0 | M8: 0 | N8: 0 | P8: 57.1
A9: USR-100008 | B9: 45794 | C9: Control | D9: South | E9: Mobile | F9: Paid Search | G9: Free | H9: 0 | I9: 0 | J9: 0 | K9: 0 | L9: 0 | M9: 0 | N9: 0 | P9: 36.4
A10: USR-100009 | B10: 45711 | C10: Control | D10: South | E10: Tablet | F10: Referral | G10: Basic | H10: 0 | I10: 0 | J10: 0 | K10: 0 | L10: 0 | M10: 0 | N10: 0 | P10: 55.4
A11: USR-100010 | B11: 45806 | C11: Control | D11: West | E11: Desktop | F11: Social | G11: Free | H11: 1 | I11: 0 | J11: 0 | K11: 0 | L11: 0 | M11: 0 | N11: 0 | P11: 57.3
A12: USR-100011 | B12: 45777 | C12: Control | D12: East | E12: Mobile | F12: Paid Search | G12: Basic | H12: 1 | I12: 1 | J12: 1 | K12: 0 | L12: 0 | M12: 0 | N12: 0 | P12: 63.6
A13: USR-100012 | B13: 45732 | C13: Control | D13: East | E13: Mobile | F13: Social | G13: Premium | H13: 1 | I13: 1 | J13: 1 | K13: 0 | L13: 0 | M13: 1 | N13: 0 | P13: 80.4
... A60: USR-100059 | B60: 45761 | C60: Control | D60: North | E60: Mobile | F60: Social | G60: Free | H60: 0 | I60: 0 | J60: 0 | K60: 0 | L60: 0 | M60: 2 | N60: 0 | P60: 48.9
A61: USR-100060 | B61: 45658 | C61: Control | D61: West | E61: Mobile | F61: Social | G61: Free | H61: 1 | I61: 1 | J61: 1 | K61: 1 | L61: 240.42 | M61: 0 | N61: 0 | O61: 16 | P61: 56.5
A62: USR-100061 | B62: 45749 | C62: Control | D62: South | E62: Mobile | F62: Referral | G62: Free | H62: 1 | I62: 0 | J62: 0 | K62: 0 | L62: 0 | M62: 0 | N62: 0 | P62: 53.7
A63: USR-100062 | B63: 45745 | C63: Control | D63: North | E63: Mobile | F63: Social | G63: Premium | H63: 0 | I63: 0 | J63: 0 | K63: 0 | L63: 0 | M63: 0 | N63: 0 | P63: 62.2
A64: USR-100063 | B64: 45792 | C64: Control | D64: South | E64: Desktop | F64: Organic | G64: Free | H64: 1 | I64: 0 | J64: 0 | K64: 0 | L64: 0 | M64: 0 | N64: 0 | P64: 50.2
A65: USR-100064 | B65: 45758 | C65: Control | D65: North | E65: Mobile | F65: Organic | G65: Basic | H65: 1 | I65: 0 | J65: 0 | K65: 0 | L65: 0 | M65: 0 | N65: 0 | P65: 74.3
A66: USR-100065 | B66: 45723 | C66: Control | D66: South | E66: Desktop | F66: Paid Search | G66: Free | H66: 1 | I66: 0 | J66: 0 | K66: 0 | L66: 0 | M66: 0 | N66: 0 | P66: 58
A67: USR-100066 | B67: 45807 | C67: Control | D67: South | E67: Mobile | F67: Organic | G67: Free | H67: 0 | I67: 0 | J67: 0 | K67: 0 | L67: 0 | M67: 0 | N67: 0 | P67: 46.7
A68: USR-100067 | B68: 45664 | C68: Control | D68: South | E68: Desktop | F68: Organic | G68: Premium | H68: 1 | I68: 0 | J68: 0 | K68: 0 | L68: 0 | M68: 1 | N68: 0 | P68: 49.6
A69: USR-100068 | B69: 45785 | C69: Control | D69: West | E69: Mobile | F69: Social | G69: Free | H69: 0 | I69: 0 | J69: 0 | K69: 0 | L69: 0 | M69: 0 | N69: 0 | P69: 60.4
A70: USR-100069 | B70: 45735 | C70: Control | D70: East | E70: Desktop | F70: Email | G70: Free | H70: 1 | I70: 1 | J70: 1 | K70: 0 | L70: 0 | M70: 0 | N70: 0 | P70: 55.3
A71: USR-100070 | B71: 45793 | C71: Control | D71: North | E71: Desktop | F71: Organic | G71: Free | H71: 0 | I71: 0 | J71: 0 | K71: 0 | L71: 0 | M71: 0 | N71: 0 | P71: 56.2
A72: USR-100071 | B72: 45724 | C72: Control | D72: West | E72: Mobile | F72: Email | G72: Free | H72: 0 | I72: 0 | J72: 0 | K72: 0 | L72: 0 | M72: 0 | N72: 0 | P72: 29.4
A73: USR-100072 | B73: 45724 | C73: Control | D73: East | E73: Mobile | F73: Email | G73: Free | H73: 1 | I73: 0 | J73: 0 | K73: 0 | L73: 0 | M73: 0 | N73: 0 | P73: 54.2
... A79: USR-100078 | B79: 45673 | C79: Control | D79: North | E79: Mobile | F79: Organic | G79: Free | H79: 0 | I79: 0 | J79: 0 | K79: 0 | L79: 0 | M79: 2 | N79: 0 | P79: 48.4
A80: USR-100079 | B80: 45708 | C80: Control | D80: West | E80: Desktop | F80: Organic | G80: Free | H80: 1 | I80: 1 | J80: 1 | K80: 1 | L80: 457.51 | M80: 0 | N80: 0 | O80: 7 | P80: 38
A81: USR-100080 | B81: 45798 | C81: Control | D81: East | E81: Mobile | F81: Social | G81: Free | H81: 1 | I81: 0 | J81: 0 | K81: 0 | L81: 0 | M81: 0 | N81: 0 | P81: 44.2
A82: USR-100081 | B82: 45785 | C82: Control | D82: South | E82: Mobile | F82: Organic | G82: Free | H82: 1 | I82: 1 | J82: 1 | K82: 0 | L82: 0 | M82: 0 | N82: 0 | P82: 81.2
A83: USR-100082 | B83: 45724 | C83: Control | D83: South | E83: Mobile | F83: Referral | G83: Free | H83: 1 | I83: 1 | J83: 0 | K83: 0 | L83: 0 | M83: 0 | N83: 0 | P83: 63.8
A84: USR-100083 | B84: 45748 | C84: Control | D84: South | E84: Desktop | F84: Email | G84: Free | H84: 0 | I84: 0 | J84: 0 | K84: 0 | L84: 0 | M84: 0 | N84: 0 | P84: 64.7
A85: USR-100084 | B85: 45719 | C85: Control | D85: West | E85: Mobile | F85: Social | G85: Basic | H85: 0 | I85: 0 | J85: 0 | K85: 0 | L85: 0 | M85: 0 | N85: 0 | P85: 60.4
A86: USR-100085 | B86: 45763 | C86: Control | D86: South | E86: Mobile | F86: Paid Search | G86: Free | H86: 0 | I86: 0 | J86: 0 | K86: 0 | L86: 0 | M86: 0 | N86: 0 | P86: 66.6
A87: USR-100086 | B87: 45666 | C87: Control | D87: North | E87: Desktop | F87: Organic | G87: Free | H87: 1 | I87: 0 | J87: 0 | K87: 0 | L87: 0 | M87: 0 | N87: 0 | P87: 50.9
A88: USR-100087 | B88: 45679 | C88: Control | D88: West | E88: Desktop | F88: Social | G88: Basic | H88: 0 | I88: 0 | J88: 0 | K88: 0 | L88: 0 | M88: 0 | N88: 0 | P88: 51
A89: USR-100088 | B89: 45777 | C89: Control | D89: South | E89: Mobile | F89: Email | G89: Premium | H89: 0 | I89: 0 | J89: 0 | K89: 0 | L89: 0 | M89: 0 | N89: 0 | P89: 65.8
A90: USR-100089 | B90: 45772 | C90: Control | D90: North | E90: Mobile | F90: Referral | G90: Basic | H90: 1 | I90: 0 | J90: 0 | K90: 0 | L90: 0 | M90: 0 | N90: 0 | P90: 61.8
A91: USR-100090 | B91: 45689 | C91: Control | D91: North | E91: Mobile | F91: Organic | G91: Basic | H91: 1 | I91: 0 | J91: 0 | K91: 0 | L91: 0 | M91: 0 | N91: 0 | P91: 54.5
...
